[2016-11-16 18:19:12,227] ERROR base.handle_uncaught_exception-[256] Internal Server Error: /api/item_list.json
Traceback (most recent call last):
  File "C:\work\open\ips\env\lib\site-packages\django\core\handlers\base.py", line 132, in get_response
    response = wrapped_callback(request, *callback_args, **callback_kwargs)
  File "C:\work\open\ips\env\lib\site-packages\django\views\decorators\csrf.py", line 58, in wrapped_view
    return view_func(*args, **kwargs)
  File "C:\work\open\ips\env\lib\site-packages\rest_framework\viewsets.py", line 87, in view
    return self.dispatch(request, *args, **kwargs)
  File "C:\work\open\ips\env\lib\site-packages\rest_framework\views.py", line 466, in dispatch
    response = self.handle_exception(exc)
  File "C:\work\open\ips\env\lib\site-packages\rest_framework\views.py", line 463, in dispatch
    response = handler(request, *args, **kwargs)
  File "C:\work\open\ips\env\lib\site-packages\rest_framework\mixins.py", line 20, in create
    serializer.is_valid(raise_exception=True)
  File "C:\work\open\ips\env\lib\site-packages\rest_framework\serializers.py", line 213, in is_valid
    self._validated_data = self.run_validation(self.initial_data)
  File "C:\work\open\ips\env\lib\site-packages\rest_framework\serializers.py", line 407, in run_validation
    value = self.to_internal_value(data)
  File "C:\work\open\ips\env\lib\site-packages\rest_framework\serializers.py", line 437, in to_internal_value
    validated_value = field.run_validation(primitive_value)
  File "C:\work\open\ips\env\lib\site-packages\rest_framework\fields.py", line 482, in run_validation
    value = self.to_internal_value(data)
  File "C:\work\open\ips\env\lib\site-packages\rest_framework\relations.py", line 463, in to_internal_value
    for item in data
  File "C:\work\open\ips\env\lib\site-packages\rest_framework\fields.py", line 516, in to_internal_value
    cls=self.__class__.__name__
NotImplementedError: StringRelatedField.to_internal_value() must be implemented.
[2016-11-16 18:19:12,227] ERROR base.handle_uncaught_exception-[256] Internal Server Error: /api/item_list.json
Traceback (most recent call last):
  File "C:\work\open\ips\env\lib\site-packages\django\core\handlers\base.py", line 132, in get_response
    response = wrapped_callback(request, *callback_args, **callback_kwargs)
  File "C:\work\open\ips\env\lib\site-packages\django\views\decorators\csrf.py", line 58, in wrapped_view
    return view_func(*args, **kwargs)
  File "C:\work\open\ips\env\lib\site-packages\rest_framework\viewsets.py", line 87, in view
    return self.dispatch(request, *args, **kwargs)
  File "C:\work\open\ips\env\lib\site-packages\rest_framework\views.py", line 466, in dispatch
    response = self.handle_exception(exc)
  File "C:\work\open\ips\env\lib\site-packages\rest_framework\views.py", line 463, in dispatch
    response = handler(request, *args, **kwargs)
  File "C:\work\open\ips\env\lib\site-packages\rest_framework\mixins.py", line 20, in create
    serializer.is_valid(raise_exception=True)
  File "C:\work\open\ips\env\lib\site-packages\rest_framework\serializers.py", line 213, in is_valid
    self._validated_data = self.run_validation(self.initial_data)
  File "C:\work\open\ips\env\lib\site-packages\rest_framework\serializers.py", line 407, in run_validation
    value = self.to_internal_value(data)
  File "C:\work\open\ips\env\lib\site-packages\rest_framework\serializers.py", line 437, in to_internal_value
    validated_value = field.run_validation(primitive_value)
  File "C:\work\open\ips\env\lib\site-packages\rest_framework\fields.py", line 482, in run_validation
    value = self.to_internal_value(data)
  File "C:\work\open\ips\env\lib\site-packages\rest_framework\relations.py", line 463, in to_internal_value
    for item in data
  File "C:\work\open\ips\env\lib\site-packages\rest_framework\fields.py", line 516, in to_internal_value
    cls=self.__class__.__name__
NotImplementedError: StringRelatedField.to_internal_value() must be implemented.
[2016-11-17 14:22:34,540] ERROR base.handle_uncaught_exception-[256] Internal Server Error: /nginx/
Traceback (most recent call last):
  File "C:\work\open\ips\env\lib\site-packages\django\core\handlers\base.py", line 119, in get_response
    resolver_match = resolver.resolve(request.path_info)
  File "C:\work\open\ips\env\lib\site-packages\django\core\urlresolvers.py", line 365, in resolve
    for pattern in self.url_patterns:
  File "C:\work\open\ips\env\lib\site-packages\django\core\urlresolvers.py", line 401, in url_patterns
    patterns = getattr(self.urlconf_module, "urlpatterns", self.urlconf_module)
  File "C:\work\open\ips\env\lib\site-packages\django\core\urlresolvers.py", line 395, in urlconf_module
    self._urlconf_module = import_module(self.urlconf_name)
  File "C:\Python27\Lib\importlib\__init__.py", line 37, in import_module
    __import__(name)
  File "C:\work\open\ips\ips\urls.py", line 27, in <module>
    url(r'^', include('webui.urls')),
  File "C:\work\open\ips\env\lib\site-packages\django\conf\urls\__init__.py", line 33, in include
    urlconf_module = import_module(urlconf_module)
  File "C:\Python27\Lib\importlib\__init__.py", line 37, in import_module
    __import__(name)
  File "C:\work\open\ips\webui\urls.py", line 3, in <module>
    from webui import views
  File "C:\work\open\ips\webui\views.py", line 521, in <module>
    class Item_check_ViewSet(Base_ListViewSet):
  File "C:\work\open\ips\webui\views.py", line 522, in Item_check_ViewSet
    Item_check.objects.all().count()
  File "C:\work\open\ips\env\lib\site-packages\django\db\models\query.py", line 318, in count
    return self.query.get_count(using=self.db)
  File "C:\work\open\ips\env\lib\site-packages\django\db\models\sql\query.py", line 466, in get_count
    number = obj.get_aggregation(using, ['__count'])['__count']
  File "C:\work\open\ips\env\lib\site-packages\django\db\models\sql\query.py", line 447, in get_aggregation
    result = compiler.execute_sql(SINGLE)
  File "C:\work\open\ips\env\lib\site-packages\django\db\models\sql\compiler.py", line 840, in execute_sql
    cursor.execute(sql, params)
  File "C:\work\open\ips\env\lib\site-packages\django\db\backends\utils.py", line 79, in execute
    return super(CursorDebugWrapper, self).execute(sql, params)
  File "C:\work\open\ips\env\lib\site-packages\django\db\backends\utils.py", line 64, in execute
    return self.cursor.execute(sql, params)
  File "C:\work\open\ips\env\lib\site-packages\django\db\utils.py", line 98, in __exit__
    six.reraise(dj_exc_type, dj_exc_value, traceback)
  File "C:\work\open\ips\env\lib\site-packages\django\db\backends\utils.py", line 64, in execute
    return self.cursor.execute(sql, params)
  File "C:\work\open\ips\env\lib\site-packages\django\db\backends\sqlite3\base.py", line 318, in execute
    return Database.Cursor.execute(self, query, params)
OperationalError: no such table: api_item_check
[2016-11-17 14:22:34,540] ERROR base.handle_uncaught_exception-[256] Internal Server Error: /nginx/
Traceback (most recent call last):
  File "C:\work\open\ips\env\lib\site-packages\django\core\handlers\base.py", line 119, in get_response
    resolver_match = resolver.resolve(request.path_info)
  File "C:\work\open\ips\env\lib\site-packages\django\core\urlresolvers.py", line 365, in resolve
    for pattern in self.url_patterns:
  File "C:\work\open\ips\env\lib\site-packages\django\core\urlresolvers.py", line 401, in url_patterns
    patterns = getattr(self.urlconf_module, "urlpatterns", self.urlconf_module)
  File "C:\work\open\ips\env\lib\site-packages\django\core\urlresolvers.py", line 395, in urlconf_module
    self._urlconf_module = import_module(self.urlconf_name)
  File "C:\Python27\Lib\importlib\__init__.py", line 37, in import_module
    __import__(name)
  File "C:\work\open\ips\ips\urls.py", line 27, in <module>
    url(r'^', include('webui.urls')),
  File "C:\work\open\ips\env\lib\site-packages\django\conf\urls\__init__.py", line 33, in include
    urlconf_module = import_module(urlconf_module)
  File "C:\Python27\Lib\importlib\__init__.py", line 37, in import_module
    __import__(name)
  File "C:\work\open\ips\webui\urls.py", line 3, in <module>
    from webui import views
  File "C:\work\open\ips\webui\views.py", line 521, in <module>
    class Item_check_ViewSet(Base_ListViewSet):
  File "C:\work\open\ips\webui\views.py", line 522, in Item_check_ViewSet
    Item_check.objects.all().count()
  File "C:\work\open\ips\env\lib\site-packages\django\db\models\query.py", line 318, in count
    return self.query.get_count(using=self.db)
  File "C:\work\open\ips\env\lib\site-packages\django\db\models\sql\query.py", line 466, in get_count
    number = obj.get_aggregation(using, ['__count'])['__count']
  File "C:\work\open\ips\env\lib\site-packages\django\db\models\sql\query.py", line 447, in get_aggregation
    result = compiler.execute_sql(SINGLE)
  File "C:\work\open\ips\env\lib\site-packages\django\db\models\sql\compiler.py", line 840, in execute_sql
    cursor.execute(sql, params)
  File "C:\work\open\ips\env\lib\site-packages\django\db\backends\utils.py", line 79, in execute
    return super(CursorDebugWrapper, self).execute(sql, params)
  File "C:\work\open\ips\env\lib\site-packages\django\db\backends\utils.py", line 64, in execute
    return self.cursor.execute(sql, params)
  File "C:\work\open\ips\env\lib\site-packages\django\db\utils.py", line 98, in __exit__
    six.reraise(dj_exc_type, dj_exc_value, traceback)
  File "C:\work\open\ips\env\lib\site-packages\django\db\backends\utils.py", line 64, in execute
    return self.cursor.execute(sql, params)
  File "C:\work\open\ips\env\lib\site-packages\django\db\backends\sqlite3\base.py", line 318, in execute
    return Database.Cursor.execute(self, query, params)
OperationalError: no such table: api_item_check
[2016-11-17 15:00:45,910] ERROR base.handle_uncaught_exception-[256] Internal Server Error: /machine/
Traceback (most recent call last):
  File "C:\work\open\ips\env\lib\site-packages\django\core\handlers\base.py", line 132, in get_response
    response = wrapped_callback(request, *callback_args, **callback_kwargs)
  File "C:\work\open\ips\env\lib\site-packages\django\contrib\auth\decorators.py", line 22, in _wrapped_view
    return view_func(request, *args, **kwargs)
  File "C:\work\open\ips\env\lib\site-packages\django\views\generic\base.py", line 71, in view
    return self.dispatch(request, *args, **kwargs)
  File "C:\work\open\ips\env\lib\site-packages\django\views\generic\base.py", line 89, in dispatch
    return handler(request, *args, **kwargs)
  File "C:\work\open\ips\env\lib\site-packages\vanilla\model_views.py", line 219, in get
    queryset = self.get_queryset()
  File "C:\work\open\ips\webui\views.py", line 113, in get_queryset
    idc=self.request.GET['idc']
  File "C:\work\open\ips\env\lib\site-packages\django\utils\datastructures.py", line 322, in __getitem__
    raise MultiValueDictKeyError(repr(key))
MultiValueDictKeyError: "'idc'"
[2016-11-17 15:00:45,910] ERROR base.handle_uncaught_exception-[256] Internal Server Error: /machine/
Traceback (most recent call last):
  File "C:\work\open\ips\env\lib\site-packages\django\core\handlers\base.py", line 132, in get_response
    response = wrapped_callback(request, *callback_args, **callback_kwargs)
  File "C:\work\open\ips\env\lib\site-packages\django\contrib\auth\decorators.py", line 22, in _wrapped_view
    return view_func(request, *args, **kwargs)
  File "C:\work\open\ips\env\lib\site-packages\django\views\generic\base.py", line 71, in view
    return self.dispatch(request, *args, **kwargs)
  File "C:\work\open\ips\env\lib\site-packages\django\views\generic\base.py", line 89, in dispatch
    return handler(request, *args, **kwargs)
  File "C:\work\open\ips\env\lib\site-packages\vanilla\model_views.py", line 219, in get
    queryset = self.get_queryset()
  File "C:\work\open\ips\webui\views.py", line 113, in get_queryset
    idc=self.request.GET['idc']
  File "C:\work\open\ips\env\lib\site-packages\django\utils\datastructures.py", line 322, in __getitem__
    raise MultiValueDictKeyError(repr(key))
MultiValueDictKeyError: "'idc'"
[2016-11-17 15:55:35,622] ERROR base.handle_uncaught_exception-[256] Internal Server Error: /
Traceback (most recent call last):
  File "C:\work\open\ips\env\lib\site-packages\django\core\handlers\base.py", line 132, in get_response
    response = wrapped_callback(request, *callback_args, **callback_kwargs)
  File "C:\work\open\ips\webui\views.py", line 28, in index
    product=[{"name":x,"number":Machine.objects.filter(compay='shihuit',product=x).count()} for x in product_list]
  File "C:\work\open\ips\env\lib\site-packages\django\db\models\manager.py", line 127, in manager_method
    return getattr(self.get_queryset(), name)(*args, **kwargs)
  File "C:\work\open\ips\env\lib\site-packages\django\db\models\query.py", line 679, in filter
    return self._filter_or_exclude(False, *args, **kwargs)
  File "C:\work\open\ips\env\lib\site-packages\django\db\models\query.py", line 697, in _filter_or_exclude
    clone.query.add_q(Q(*args, **kwargs))
  File "C:\work\open\ips\env\lib\site-packages\django\db\models\sql\query.py", line 1310, in add_q
    clause, require_inner = self._add_q(where_part, self.used_aliases)
  File "C:\work\open\ips\env\lib\site-packages\django\db\models\sql\query.py", line 1338, in _add_q
    allow_joins=allow_joins, split_subq=split_subq,
  File "C:\work\open\ips\env\lib\site-packages\django\db\models\sql\query.py", line 1150, in build_filter
    lookups, parts, reffed_expression = self.solve_lookup_type(arg)
  File "C:\work\open\ips\env\lib\site-packages\django\db\models\sql\query.py", line 1036, in solve_lookup_type
    _, field, _, lookup_parts = self.names_to_path(lookup_splitted, self.get_meta())
  File "C:\work\open\ips\env\lib\site-packages\django\db\models\sql\query.py", line 1397, in names_to_path
    "Choices are: %s" % (name, ", ".join(available)))
FieldError: Cannot resolve keyword 'compay' into field. Choices are: company, cpu, created_date, id, idc, ips, machine_id, major_release, memory, modified_date, name, product, serial, sys_desc, system_id
[2016-11-17 15:55:35,622] ERROR base.handle_uncaught_exception-[256] Internal Server Error: /
Traceback (most recent call last):
  File "C:\work\open\ips\env\lib\site-packages\django\core\handlers\base.py", line 132, in get_response
    response = wrapped_callback(request, *callback_args, **callback_kwargs)
  File "C:\work\open\ips\webui\views.py", line 28, in index
    product=[{"name":x,"number":Machine.objects.filter(compay='shihuit',product=x).count()} for x in product_list]
  File "C:\work\open\ips\env\lib\site-packages\django\db\models\manager.py", line 127, in manager_method
    return getattr(self.get_queryset(), name)(*args, **kwargs)
  File "C:\work\open\ips\env\lib\site-packages\django\db\models\query.py", line 679, in filter
    return self._filter_or_exclude(False, *args, **kwargs)
  File "C:\work\open\ips\env\lib\site-packages\django\db\models\query.py", line 697, in _filter_or_exclude
    clone.query.add_q(Q(*args, **kwargs))
  File "C:\work\open\ips\env\lib\site-packages\django\db\models\sql\query.py", line 1310, in add_q
    clause, require_inner = self._add_q(where_part, self.used_aliases)
  File "C:\work\open\ips\env\lib\site-packages\django\db\models\sql\query.py", line 1338, in _add_q
    allow_joins=allow_joins, split_subq=split_subq,
  File "C:\work\open\ips\env\lib\site-packages\django\db\models\sql\query.py", line 1150, in build_filter
    lookups, parts, reffed_expression = self.solve_lookup_type(arg)
  File "C:\work\open\ips\env\lib\site-packages\django\db\models\sql\query.py", line 1036, in solve_lookup_type
    _, field, _, lookup_parts = self.names_to_path(lookup_splitted, self.get_meta())
  File "C:\work\open\ips\env\lib\site-packages\django\db\models\sql\query.py", line 1397, in names_to_path
    "Choices are: %s" % (name, ", ".join(available)))
FieldError: Cannot resolve keyword 'compay' into field. Choices are: company, cpu, created_date, id, idc, ips, machine_id, major_release, memory, modified_date, name, product, serial, sys_desc, system_id
[2016-11-17 16:16:10,269] ERROR base.handle_uncaught_exception-[256] Internal Server Error: /application/create/
Traceback (most recent call last):
  File "C:\work\open\ips\env\lib\site-packages\django\core\handlers\base.py", line 132, in get_response
    response = wrapped_callback(request, *callback_args, **callback_kwargs)
  File "C:\work\open\ips\env\lib\site-packages\django\contrib\auth\decorators.py", line 22, in _wrapped_view
    return view_func(request, *args, **kwargs)
  File "C:\work\open\ips\env\lib\site-packages\django\views\generic\base.py", line 71, in view
    return self.dispatch(request, *args, **kwargs)
  File "C:\work\open\ips\env\lib\site-packages\django\views\generic\base.py", line 89, in dispatch
    return handler(request, *args, **kwargs)
  File "C:\work\open\ips\env\lib\site-packages\vanilla\model_views.py", line 260, in get
    form = self.get_form()
  File "C:\work\open\ips\env\lib\site-packages\vanilla\model_views.py", line 98, in get_form
    return cls(data=data, files=files, **kwargs)
  File "C:\work\open\ips\env\lib\site-packages\django\db\models\base.py", line 480, in __init__
    raise TypeError("'%s' is an invalid keyword argument for this function" % list(kwargs)[0])
TypeError: 'files' is an invalid keyword argument for this function
[2016-11-17 16:16:10,269] ERROR base.handle_uncaught_exception-[256] Internal Server Error: /application/create/
Traceback (most recent call last):
  File "C:\work\open\ips\env\lib\site-packages\django\core\handlers\base.py", line 132, in get_response
    response = wrapped_callback(request, *callback_args, **callback_kwargs)
  File "C:\work\open\ips\env\lib\site-packages\django\contrib\auth\decorators.py", line 22, in _wrapped_view
    return view_func(request, *args, **kwargs)
  File "C:\work\open\ips\env\lib\site-packages\django\views\generic\base.py", line 71, in view
    return self.dispatch(request, *args, **kwargs)
  File "C:\work\open\ips\env\lib\site-packages\django\views\generic\base.py", line 89, in dispatch
    return handler(request, *args, **kwargs)
  File "C:\work\open\ips\env\lib\site-packages\vanilla\model_views.py", line 260, in get
    form = self.get_form()
  File "C:\work\open\ips\env\lib\site-packages\vanilla\model_views.py", line 98, in get_form
    return cls(data=data, files=files, **kwargs)
  File "C:\work\open\ips\env\lib\site-packages\django\db\models\base.py", line 480, in __init__
    raise TypeError("'%s' is an invalid keyword argument for this function" % list(kwargs)[0])
TypeError: 'files' is an invalid keyword argument for this function
[2016-11-25 15:15:09,137] ERROR base.handle_uncaught_exception-[256] Internal Server Error: /
Traceback (most recent call last):
  File "C:\work\open\ips\env\lib\site-packages\django\core\handlers\base.py", line 119, in get_response
    resolver_match = resolver.resolve(request.path_info)
  File "C:\work\open\ips\env\lib\site-packages\django\core\urlresolvers.py", line 365, in resolve
    for pattern in self.url_patterns:
  File "C:\work\open\ips\env\lib\site-packages\django\core\urlresolvers.py", line 401, in url_patterns
    patterns = getattr(self.urlconf_module, "urlpatterns", self.urlconf_module)
  File "C:\work\open\ips\env\lib\site-packages\django\core\urlresolvers.py", line 395, in urlconf_module
    self._urlconf_module = import_module(self.urlconf_name)
  File "C:\Python27\Lib\importlib\__init__.py", line 37, in import_module
    __import__(name)
  File "C:\work\open\ips\ips\urls.py", line 26, in <module>
    url(r'^api/', include('api.urls')),
  File "C:\work\open\ips\env\lib\site-packages\django\conf\urls\__init__.py", line 33, in include
    urlconf_module = import_module(urlconf_module)
  File "C:\Python27\Lib\importlib\__init__.py", line 37, in import_module
    __import__(name)
  File "C:\work\open\ips\api\urls.py", line 19, in <module>
    router.register(r'redis', views.Redis_ApiViewSet)
AttributeError: 'module' object has no attribute 'Redis_ApiViewSet'
[2016-11-25 15:15:09,137] ERROR base.handle_uncaught_exception-[256] Internal Server Error: /
Traceback (most recent call last):
  File "C:\work\open\ips\env\lib\site-packages\django\core\handlers\base.py", line 119, in get_response
    resolver_match = resolver.resolve(request.path_info)
  File "C:\work\open\ips\env\lib\site-packages\django\core\urlresolvers.py", line 365, in resolve
    for pattern in self.url_patterns:
  File "C:\work\open\ips\env\lib\site-packages\django\core\urlresolvers.py", line 401, in url_patterns
    patterns = getattr(self.urlconf_module, "urlpatterns", self.urlconf_module)
  File "C:\work\open\ips\env\lib\site-packages\django\core\urlresolvers.py", line 395, in urlconf_module
    self._urlconf_module = import_module(self.urlconf_name)
  File "C:\Python27\Lib\importlib\__init__.py", line 37, in import_module
    __import__(name)
  File "C:\work\open\ips\ips\urls.py", line 26, in <module>
    url(r'^api/', include('api.urls')),
  File "C:\work\open\ips\env\lib\site-packages\django\conf\urls\__init__.py", line 33, in include
    urlconf_module = import_module(urlconf_module)
  File "C:\Python27\Lib\importlib\__init__.py", line 37, in import_module
    __import__(name)
  File "C:\work\open\ips\api\urls.py", line 19, in <module>
    router.register(r'redis', views.Redis_ApiViewSet)
AttributeError: 'module' object has no attribute 'Redis_ApiViewSet'
[2016-12-07 14:36:52,444] ERROR base.handle_uncaught_exception-[256] Internal Server Error: /item/deploy/detail/
Traceback (most recent call last):
  File "C:\work\open\ips\env\lib\site-packages\django\core\handlers\base.py", line 132, in get_response
    response = wrapped_callback(request, *callback_args, **callback_kwargs)
  File "C:\work\open\ips\env\lib\site-packages\django\contrib\auth\decorators.py", line 22, in _wrapped_view
    return view_func(request, *args, **kwargs)
  File "C:\work\open\ips\env\lib\site-packages\django\views\generic\base.py", line 71, in view
    return self.dispatch(request, *args, **kwargs)
  File "C:\work\open\ips\env\lib\site-packages\django\views\generic\base.py", line 89, in dispatch
    return handler(request, *args, **kwargs)
  File "C:\work\open\ips\env\lib\site-packages\django\views\generic\base.py", line 158, in get
    context = self.get_context_data(**kwargs)
  File "C:\work\open\ips\webui\views.py", line 692, in get_context_data
    context['site_count'] = site_all.count()
TypeError: count() takes exactly one argument (0 given)
[2016-12-07 14:36:52,444] ERROR base.handle_uncaught_exception-[256] Internal Server Error: /item/deploy/detail/
Traceback (most recent call last):
  File "C:\work\open\ips\env\lib\site-packages\django\core\handlers\base.py", line 132, in get_response
    response = wrapped_callback(request, *callback_args, **callback_kwargs)
  File "C:\work\open\ips\env\lib\site-packages\django\contrib\auth\decorators.py", line 22, in _wrapped_view
    return view_func(request, *args, **kwargs)
  File "C:\work\open\ips\env\lib\site-packages\django\views\generic\base.py", line 71, in view
    return self.dispatch(request, *args, **kwargs)
  File "C:\work\open\ips\env\lib\site-packages\django\views\generic\base.py", line 89, in dispatch
    return handler(request, *args, **kwargs)
  File "C:\work\open\ips\env\lib\site-packages\django\views\generic\base.py", line 158, in get
    context = self.get_context_data(**kwargs)
  File "C:\work\open\ips\webui\views.py", line 692, in get_context_data
    context['site_count'] = site_all.count()
TypeError: count() takes exactly one argument (0 given)
[2016-12-14 16:31:26,042] ERROR base.handle_uncaught_exception-[256] Internal Server Error: /item-name/
Traceback (most recent call last):
  File "C:\work\open\ips\env\lib\site-packages\django\core\handlers\base.py", line 164, in get_response
    response = response.render()
  File "C:\work\open\ips\env\lib\site-packages\django\template\response.py", line 158, in render
    self.content = self.rendered_content
  File "C:\work\open\ips\env\lib\site-packages\django\template\response.py", line 135, in rendered_content
    content = template.render(context, self._request)
  File "C:\work\open\ips\env\lib\site-packages\django\template\backends\django.py", line 74, in render
    return self.template.render(context)
  File "C:\work\open\ips\env\lib\site-packages\django\template\base.py", line 210, in render
    return self._render(context)
  File "C:\work\open\ips\env\lib\site-packages\django\template\base.py", line 202, in _render
    return self.nodelist.render(context)
  File "C:\work\open\ips\env\lib\site-packages\django\template\base.py", line 905, in render
    bit = self.render_node(node, context)
  File "C:\work\open\ips\env\lib\site-packages\django\template\debug.py", line 79, in render_node
    return node.render(context)
  File "C:\work\open\ips\env\lib\site-packages\django\template\loader_tags.py", line 135, in render
    return compiled_parent._render(context)
  File "C:\work\open\ips\env\lib\site-packages\django\template\base.py", line 202, in _render
    return self.nodelist.render(context)
  File "C:\work\open\ips\env\lib\site-packages\django\template\base.py", line 905, in render
    bit = self.render_node(node, context)
  File "C:\work\open\ips\env\lib\site-packages\django\template\debug.py", line 79, in render_node
    return node.render(context)
  File "C:\work\open\ips\env\lib\site-packages\django\template\loader_tags.py", line 135, in render
    return compiled_parent._render(context)
  File "C:\work\open\ips\env\lib\site-packages\django\template\base.py", line 202, in _render
    return self.nodelist.render(context)
  File "C:\work\open\ips\env\lib\site-packages\django\template\base.py", line 905, in render
    bit = self.render_node(node, context)
  File "C:\work\open\ips\env\lib\site-packages\django\template\debug.py", line 79, in render_node
    return node.render(context)
  File "C:\work\open\ips\env\lib\site-packages\django\template\loader_tags.py", line 65, in render
    result = block.nodelist.render(context)
  File "C:\work\open\ips\env\lib\site-packages\django\template\base.py", line 905, in render
    bit = self.render_node(node, context)
  File "C:\work\open\ips\env\lib\site-packages\django\template\debug.py", line 79, in render_node
    return node.render(context)
  File "C:\work\open\ips\env\lib\site-packages\django\template\defaulttags.py", line 217, in render
    nodelist.append(node.render(context))
  File "C:\work\open\ips\env\lib\site-packages\django\template\defaulttags.py", line 507, in render
    six.reraise(*exc_info)
  File "C:\work\open\ips\env\lib\site-packages\django\template\defaulttags.py", line 493, in render
    url = reverse(view_name, args=args, kwargs=kwargs, current_app=current_app)
  File "C:\work\open\ips\env\lib\site-packages\django\core\urlresolvers.py", line 578, in reverse
    return force_text(iri_to_uri(resolver._reverse_with_prefix(view, prefix, *args, **kwargs)))
  File "C:\work\open\ips\env\lib\site-packages\django\core\urlresolvers.py", line 495, in _reverse_with_prefix
    (lookup_view_s, args, kwargs, len(patterns), patterns))
NoReverseMatch: Reverse for 'item-list-detail' with arguments '('',)' and keyword arguments '{}' not found. 1 pattern(s) tried: ['item/detail/(?P<pk>\\d+)/$']
[2016-12-14 16:31:26,042] ERROR base.handle_uncaught_exception-[256] Internal Server Error: /item-name/
Traceback (most recent call last):
  File "C:\work\open\ips\env\lib\site-packages\django\core\handlers\base.py", line 164, in get_response
    response = response.render()
  File "C:\work\open\ips\env\lib\site-packages\django\template\response.py", line 158, in render
    self.content = self.rendered_content
  File "C:\work\open\ips\env\lib\site-packages\django\template\response.py", line 135, in rendered_content
    content = template.render(context, self._request)
  File "C:\work\open\ips\env\lib\site-packages\django\template\backends\django.py", line 74, in render
    return self.template.render(context)
  File "C:\work\open\ips\env\lib\site-packages\django\template\base.py", line 210, in render
    return self._render(context)
  File "C:\work\open\ips\env\lib\site-packages\django\template\base.py", line 202, in _render
    return self.nodelist.render(context)
  File "C:\work\open\ips\env\lib\site-packages\django\template\base.py", line 905, in render
    bit = self.render_node(node, context)
  File "C:\work\open\ips\env\lib\site-packages\django\template\debug.py", line 79, in render_node
    return node.render(context)
  File "C:\work\open\ips\env\lib\site-packages\django\template\loader_tags.py", line 135, in render
    return compiled_parent._render(context)
  File "C:\work\open\ips\env\lib\site-packages\django\template\base.py", line 202, in _render
    return self.nodelist.render(context)
  File "C:\work\open\ips\env\lib\site-packages\django\template\base.py", line 905, in render
    bit = self.render_node(node, context)
  File "C:\work\open\ips\env\lib\site-packages\django\template\debug.py", line 79, in render_node
    return node.render(context)
  File "C:\work\open\ips\env\lib\site-packages\django\template\loader_tags.py", line 135, in render
    return compiled_parent._render(context)
  File "C:\work\open\ips\env\lib\site-packages\django\template\base.py", line 202, in _render
    return self.nodelist.render(context)
  File "C:\work\open\ips\env\lib\site-packages\django\template\base.py", line 905, in render
    bit = self.render_node(node, context)
  File "C:\work\open\ips\env\lib\site-packages\django\template\debug.py", line 79, in render_node
    return node.render(context)
  File "C:\work\open\ips\env\lib\site-packages\django\template\loader_tags.py", line 65, in render
    result = block.nodelist.render(context)
  File "C:\work\open\ips\env\lib\site-packages\django\template\base.py", line 905, in render
    bit = self.render_node(node, context)
  File "C:\work\open\ips\env\lib\site-packages\django\template\debug.py", line 79, in render_node
    return node.render(context)
  File "C:\work\open\ips\env\lib\site-packages\django\template\defaulttags.py", line 217, in render
    nodelist.append(node.render(context))
  File "C:\work\open\ips\env\lib\site-packages\django\template\defaulttags.py", line 507, in render
    six.reraise(*exc_info)
  File "C:\work\open\ips\env\lib\site-packages\django\template\defaulttags.py", line 493, in render
    url = reverse(view_name, args=args, kwargs=kwargs, current_app=current_app)
  File "C:\work\open\ips\env\lib\site-packages\django\core\urlresolvers.py", line 578, in reverse
    return force_text(iri_to_uri(resolver._reverse_with_prefix(view, prefix, *args, **kwargs)))
  File "C:\work\open\ips\env\lib\site-packages\django\core\urlresolvers.py", line 495, in _reverse_with_prefix
    (lookup_view_s, args, kwargs, len(patterns), patterns))
NoReverseMatch: Reverse for 'item-list-detail' with arguments '('',)' and keyword arguments '{}' not found. 1 pattern(s) tried: ['item/detail/(?P<pk>\\d+)/$']
[2016-12-14 16:33:28,382] ERROR base.handle_uncaught_exception-[256] Internal Server Error: /item-name/
Traceback (most recent call last):
  File "C:\work\open\ips\env\lib\site-packages\django\core\handlers\base.py", line 164, in get_response
    response = response.render()
  File "C:\work\open\ips\env\lib\site-packages\django\template\response.py", line 158, in render
    self.content = self.rendered_content
  File "C:\work\open\ips\env\lib\site-packages\django\template\response.py", line 135, in rendered_content
    content = template.render(context, self._request)
  File "C:\work\open\ips\env\lib\site-packages\django\template\backends\django.py", line 74, in render
    return self.template.render(context)
  File "C:\work\open\ips\env\lib\site-packages\django\template\base.py", line 210, in render
    return self._render(context)
  File "C:\work\open\ips\env\lib\site-packages\django\template\base.py", line 202, in _render
    return self.nodelist.render(context)
  File "C:\work\open\ips\env\lib\site-packages\django\template\base.py", line 905, in render
    bit = self.render_node(node, context)
  File "C:\work\open\ips\env\lib\site-packages\django\template\debug.py", line 79, in render_node
    return node.render(context)
  File "C:\work\open\ips\env\lib\site-packages\django\template\loader_tags.py", line 135, in render
    return compiled_parent._render(context)
  File "C:\work\open\ips\env\lib\site-packages\django\template\base.py", line 202, in _render
    return self.nodelist.render(context)
  File "C:\work\open\ips\env\lib\site-packages\django\template\base.py", line 905, in render
    bit = self.render_node(node, context)
  File "C:\work\open\ips\env\lib\site-packages\django\template\debug.py", line 79, in render_node
    return node.render(context)
  File "C:\work\open\ips\env\lib\site-packages\django\template\loader_tags.py", line 135, in render
    return compiled_parent._render(context)
  File "C:\work\open\ips\env\lib\site-packages\django\template\base.py", line 202, in _render
    return self.nodelist.render(context)
  File "C:\work\open\ips\env\lib\site-packages\django\template\base.py", line 905, in render
    bit = self.render_node(node, context)
  File "C:\work\open\ips\env\lib\site-packages\django\template\debug.py", line 79, in render_node
    return node.render(context)
  File "C:\work\open\ips\env\lib\site-packages\django\template\loader_tags.py", line 65, in render
    result = block.nodelist.render(context)
  File "C:\work\open\ips\env\lib\site-packages\django\template\base.py", line 905, in render
    bit = self.render_node(node, context)
  File "C:\work\open\ips\env\lib\site-packages\django\template\debug.py", line 79, in render_node
    return node.render(context)
  File "C:\work\open\ips\env\lib\site-packages\django\template\defaulttags.py", line 217, in render
    nodelist.append(node.render(context))
  File "C:\work\open\ips\env\lib\site-packages\django\template\defaulttags.py", line 507, in render
    six.reraise(*exc_info)
  File "C:\work\open\ips\env\lib\site-packages\django\template\defaulttags.py", line 493, in render
    url = reverse(view_name, args=args, kwargs=kwargs, current_app=current_app)
  File "C:\work\open\ips\env\lib\site-packages\django\core\urlresolvers.py", line 578, in reverse
    return force_text(iri_to_uri(resolver._reverse_with_prefix(view, prefix, *args, **kwargs)))
  File "C:\work\open\ips\env\lib\site-packages\django\core\urlresolvers.py", line 495, in _reverse_with_prefix
    (lookup_view_s, args, kwargs, len(patterns), patterns))
NoReverseMatch: Reverse for 'item-list-detail' with arguments '('',)' and keyword arguments '{}' not found. 1 pattern(s) tried: ['item/detail/(?P<pk>\\d+)/$']
[2016-12-14 16:33:28,382] ERROR base.handle_uncaught_exception-[256] Internal Server Error: /item-name/
Traceback (most recent call last):
  File "C:\work\open\ips\env\lib\site-packages\django\core\handlers\base.py", line 164, in get_response
    response = response.render()
  File "C:\work\open\ips\env\lib\site-packages\django\template\response.py", line 158, in render
    self.content = self.rendered_content
  File "C:\work\open\ips\env\lib\site-packages\django\template\response.py", line 135, in rendered_content
    content = template.render(context, self._request)
  File "C:\work\open\ips\env\lib\site-packages\django\template\backends\django.py", line 74, in render
    return self.template.render(context)
  File "C:\work\open\ips\env\lib\site-packages\django\template\base.py", line 210, in render
    return self._render(context)
  File "C:\work\open\ips\env\lib\site-packages\django\template\base.py", line 202, in _render
    return self.nodelist.render(context)
  File "C:\work\open\ips\env\lib\site-packages\django\template\base.py", line 905, in render
    bit = self.render_node(node, context)
  File "C:\work\open\ips\env\lib\site-packages\django\template\debug.py", line 79, in render_node
    return node.render(context)
  File "C:\work\open\ips\env\lib\site-packages\django\template\loader_tags.py", line 135, in render
    return compiled_parent._render(context)
  File "C:\work\open\ips\env\lib\site-packages\django\template\base.py", line 202, in _render
    return self.nodelist.render(context)
  File "C:\work\open\ips\env\lib\site-packages\django\template\base.py", line 905, in render
    bit = self.render_node(node, context)
  File "C:\work\open\ips\env\lib\site-packages\django\template\debug.py", line 79, in render_node
    return node.render(context)
  File "C:\work\open\ips\env\lib\site-packages\django\template\loader_tags.py", line 135, in render
    return compiled_parent._render(context)
  File "C:\work\open\ips\env\lib\site-packages\django\template\base.py", line 202, in _render
    return self.nodelist.render(context)
  File "C:\work\open\ips\env\lib\site-packages\django\template\base.py", line 905, in render
    bit = self.render_node(node, context)
  File "C:\work\open\ips\env\lib\site-packages\django\template\debug.py", line 79, in render_node
    return node.render(context)
  File "C:\work\open\ips\env\lib\site-packages\django\template\loader_tags.py", line 65, in render
    result = block.nodelist.render(context)
  File "C:\work\open\ips\env\lib\site-packages\django\template\base.py", line 905, in render
    bit = self.render_node(node, context)
  File "C:\work\open\ips\env\lib\site-packages\django\template\debug.py", line 79, in render_node
    return node.render(context)
  File "C:\work\open\ips\env\lib\site-packages\django\template\defaulttags.py", line 217, in render
    nodelist.append(node.render(context))
  File "C:\work\open\ips\env\lib\site-packages\django\template\defaulttags.py", line 507, in render
    six.reraise(*exc_info)
  File "C:\work\open\ips\env\lib\site-packages\django\template\defaulttags.py", line 493, in render
    url = reverse(view_name, args=args, kwargs=kwargs, current_app=current_app)
  File "C:\work\open\ips\env\lib\site-packages\django\core\urlresolvers.py", line 578, in reverse
    return force_text(iri_to_uri(resolver._reverse_with_prefix(view, prefix, *args, **kwargs)))
  File "C:\work\open\ips\env\lib\site-packages\django\core\urlresolvers.py", line 495, in _reverse_with_prefix
    (lookup_view_s, args, kwargs, len(patterns), patterns))
NoReverseMatch: Reverse for 'item-list-detail' with arguments '('',)' and keyword arguments '{}' not found. 1 pattern(s) tried: ['item/detail/(?P<pk>\\d+)/$']
[2016-12-14 16:43:53,375] ERROR base.handle_uncaught_exception-[256] Internal Server Error: /item-name/
Traceback (most recent call last):
  File "C:\work\open\ips\env\lib\site-packages\django\core\handlers\base.py", line 164, in get_response
    response = response.render()
  File "C:\work\open\ips\env\lib\site-packages\django\template\response.py", line 158, in render
    self.content = self.rendered_content
  File "C:\work\open\ips\env\lib\site-packages\django\template\response.py", line 135, in rendered_content
    content = template.render(context, self._request)
  File "C:\work\open\ips\env\lib\site-packages\django\template\backends\django.py", line 74, in render
    return self.template.render(context)
  File "C:\work\open\ips\env\lib\site-packages\django\template\base.py", line 210, in render
    return self._render(context)
  File "C:\work\open\ips\env\lib\site-packages\django\template\base.py", line 202, in _render
    return self.nodelist.render(context)
  File "C:\work\open\ips\env\lib\site-packages\django\template\base.py", line 905, in render
    bit = self.render_node(node, context)
  File "C:\work\open\ips\env\lib\site-packages\django\template\debug.py", line 79, in render_node
    return node.render(context)
  File "C:\work\open\ips\env\lib\site-packages\django\template\loader_tags.py", line 135, in render
    return compiled_parent._render(context)
  File "C:\work\open\ips\env\lib\site-packages\django\template\base.py", line 202, in _render
    return self.nodelist.render(context)
  File "C:\work\open\ips\env\lib\site-packages\django\template\base.py", line 905, in render
    bit = self.render_node(node, context)
  File "C:\work\open\ips\env\lib\site-packages\django\template\debug.py", line 79, in render_node
    return node.render(context)
  File "C:\work\open\ips\env\lib\site-packages\django\template\loader_tags.py", line 135, in render
    return compiled_parent._render(context)
  File "C:\work\open\ips\env\lib\site-packages\django\template\base.py", line 202, in _render
    return self.nodelist.render(context)
  File "C:\work\open\ips\env\lib\site-packages\django\template\base.py", line 905, in render
    bit = self.render_node(node, context)
  File "C:\work\open\ips\env\lib\site-packages\django\template\debug.py", line 79, in render_node
    return node.render(context)
  File "C:\work\open\ips\env\lib\site-packages\django\template\loader_tags.py", line 65, in render
    result = block.nodelist.render(context)
  File "C:\work\open\ips\env\lib\site-packages\django\template\base.py", line 905, in render
    bit = self.render_node(node, context)
  File "C:\work\open\ips\env\lib\site-packages\django\template\debug.py", line 79, in render_node
    return node.render(context)
  File "C:\work\open\ips\env\lib\site-packages\django\template\defaulttags.py", line 217, in render
    nodelist.append(node.render(context))
  File "C:\work\open\ips\env\lib\site-packages\django\template\defaulttags.py", line 507, in render
    six.reraise(*exc_info)
  File "C:\work\open\ips\env\lib\site-packages\django\template\defaulttags.py", line 493, in render
    url = reverse(view_name, args=args, kwargs=kwargs, current_app=current_app)
  File "C:\work\open\ips\env\lib\site-packages\django\core\urlresolvers.py", line 578, in reverse
    return force_text(iri_to_uri(resolver._reverse_with_prefix(view, prefix, *args, **kwargs)))
  File "C:\work\open\ips\env\lib\site-packages\django\core\urlresolvers.py", line 495, in _reverse_with_prefix
    (lookup_view_s, args, kwargs, len(patterns), patterns))
NoReverseMatch: Reverse for 'item-list-detail' with arguments '('',)' and keyword arguments '{}' not found. 1 pattern(s) tried: ['item/detail/(?P<pk>\\d+)/$']
[2016-12-14 16:43:53,375] ERROR base.handle_uncaught_exception-[256] Internal Server Error: /item-name/
Traceback (most recent call last):
  File "C:\work\open\ips\env\lib\site-packages\django\core\handlers\base.py", line 164, in get_response
    response = response.render()
  File "C:\work\open\ips\env\lib\site-packages\django\template\response.py", line 158, in render
    self.content = self.rendered_content
  File "C:\work\open\ips\env\lib\site-packages\django\template\response.py", line 135, in rendered_content
    content = template.render(context, self._request)
  File "C:\work\open\ips\env\lib\site-packages\django\template\backends\django.py", line 74, in render
    return self.template.render(context)
  File "C:\work\open\ips\env\lib\site-packages\django\template\base.py", line 210, in render
    return self._render(context)
  File "C:\work\open\ips\env\lib\site-packages\django\template\base.py", line 202, in _render
    return self.nodelist.render(context)
  File "C:\work\open\ips\env\lib\site-packages\django\template\base.py", line 905, in render
    bit = self.render_node(node, context)
  File "C:\work\open\ips\env\lib\site-packages\django\template\debug.py", line 79, in render_node
    return node.render(context)
  File "C:\work\open\ips\env\lib\site-packages\django\template\loader_tags.py", line 135, in render
    return compiled_parent._render(context)
  File "C:\work\open\ips\env\lib\site-packages\django\template\base.py", line 202, in _render
    return self.nodelist.render(context)
  File "C:\work\open\ips\env\lib\site-packages\django\template\base.py", line 905, in render
    bit = self.render_node(node, context)
  File "C:\work\open\ips\env\lib\site-packages\django\template\debug.py", line 79, in render_node
    return node.render(context)
  File "C:\work\open\ips\env\lib\site-packages\django\template\loader_tags.py", line 135, in render
    return compiled_parent._render(context)
  File "C:\work\open\ips\env\lib\site-packages\django\template\base.py", line 202, in _render
    return self.nodelist.render(context)
  File "C:\work\open\ips\env\lib\site-packages\django\template\base.py", line 905, in render
    bit = self.render_node(node, context)
  File "C:\work\open\ips\env\lib\site-packages\django\template\debug.py", line 79, in render_node
    return node.render(context)
  File "C:\work\open\ips\env\lib\site-packages\django\template\loader_tags.py", line 65, in render
    result = block.nodelist.render(context)
  File "C:\work\open\ips\env\lib\site-packages\django\template\base.py", line 905, in render
    bit = self.render_node(node, context)
  File "C:\work\open\ips\env\lib\site-packages\django\template\debug.py", line 79, in render_node
    return node.render(context)
  File "C:\work\open\ips\env\lib\site-packages\django\template\defaulttags.py", line 217, in render
    nodelist.append(node.render(context))
  File "C:\work\open\ips\env\lib\site-packages\django\template\defaulttags.py", line 507, in render
    six.reraise(*exc_info)
  File "C:\work\open\ips\env\lib\site-packages\django\template\defaulttags.py", line 493, in render
    url = reverse(view_name, args=args, kwargs=kwargs, current_app=current_app)
  File "C:\work\open\ips\env\lib\site-packages\django\core\urlresolvers.py", line 578, in reverse
    return force_text(iri_to_uri(resolver._reverse_with_prefix(view, prefix, *args, **kwargs)))
  File "C:\work\open\ips\env\lib\site-packages\django\core\urlresolvers.py", line 495, in _reverse_with_prefix
    (lookup_view_s, args, kwargs, len(patterns), patterns))
NoReverseMatch: Reverse for 'item-list-detail' with arguments '('',)' and keyword arguments '{}' not found. 1 pattern(s) tried: ['item/detail/(?P<pk>\\d+)/$']
[2016-12-19 11:34:37,009] ERROR base.handle_uncaught_exception-[256] Internal Server Error: /item_fun/
Traceback (most recent call last):
  File "C:\work\open\ips\env\lib\site-packages\django\core\handlers\base.py", line 132, in get_response
    response = wrapped_callback(request, *callback_args, **callback_kwargs)
  File "C:\work\open\ips\env\lib\site-packages\django\contrib\auth\decorators.py", line 22, in _wrapped_view
    return view_func(request, *args, **kwargs)
  File "C:\work\open\ips\webui\views.py", line 872, in Item_query
    response = render(req,'api/item_query.html',{"item_list":item_list,
UnboundLocalError: local variable 'item_list' referenced before assignment
[2016-12-19 11:34:37,009] ERROR base.handle_uncaught_exception-[256] Internal Server Error: /item_fun/
Traceback (most recent call last):
  File "C:\work\open\ips\env\lib\site-packages\django\core\handlers\base.py", line 132, in get_response
    response = wrapped_callback(request, *callback_args, **callback_kwargs)
  File "C:\work\open\ips\env\lib\site-packages\django\contrib\auth\decorators.py", line 22, in _wrapped_view
    return view_func(request, *args, **kwargs)
  File "C:\work\open\ips\webui\views.py", line 872, in Item_query
    response = render(req,'api/item_query.html',{"item_list":item_list,
UnboundLocalError: local variable 'item_list' referenced before assignment
